[2019-07-01 16:35:49 +0000] [18413] [DEBUG] Current configuration:
  config: None
  bind: ['unix:/home/ubuntu/workspace/spoti_env/run/gunicorn.sock']
  backlog: 2048
  workers: 3
  worker_class: sync
  threads: 1
  worker_connections: 1000
  max_requests: 0
  max_requests_jitter: 0
  timeout: 30
  graceful_timeout: 30
  keepalive: 2
  limit_request_line: 4094
  limit_request_fields: 100
  limit_request_field_size: 8190
  reload: False
  reload_engine: auto
  reload_extra_files: []
  spew: False
  check_config: False
  preload_app: False
  sendfile: None
  reuse_port: False
  chdir: /home/ubuntu/workspace/spoti_env/spotifollow/spotifollow
  daemon: False
  raw_env: []
  pidfile: None
  worker_tmp_dir: None
  user: 998
  group: 998
  umask: 0
  initgroups: False
  tmp_upload_dir: None
  secure_scheme_headers: {'X-FORWARDED-PROTOCOL': 'ssl', 'X-FORWARDED-PROTO': 'https', 'X-FORWARDED-SSL': 'on'}
  forwarded_allow_ips: ['127.0.0.1']
  accesslog: None
  disable_redirect_access_to_syslog: False
  access_log_format: %(h)s %(l)s %(u)s %(t)s "%(r)s" %(s)s %(b)s "%(f)s" "%(a)s"
  errorlog: /home/ubuntu/workspace/spoti_env/spotifollow/spotifollow/spotifollow.log
  loglevel: debug
  capture_output: False
  logger_class: gunicorn.glogging.Logger
  logconfig: None
  logconfig_dict: {}
  syslog_addr: udp://localhost:514
  syslog: False
  syslog_prefix: None
  syslog_facility: user
  enable_stdio_inheritance: False
  statsd_host: None
  statsd_prefix: 
  proc_name: spotifollow_app
  default_proc_name: spotifollow.wsgi:application
  pythonpath: None
  paste: None
  on_starting: <function OnStarting.on_starting at 0x7f3ca59a9950>
  on_reload: <function OnReload.on_reload at 0x7f3ca59a9a60>
  when_ready: <function WhenReady.when_ready at 0x7f3ca59a9b70>
  pre_fork: <function Prefork.pre_fork at 0x7f3ca59a9c80>
  post_fork: <function Postfork.post_fork at 0x7f3ca59a9d90>
  post_worker_init: <function PostWorkerInit.post_worker_init at 0x7f3ca59a9ea0>
  worker_int: <function WorkerInt.worker_int at 0x7f3ca54b9048>
  worker_abort: <function WorkerAbort.worker_abort at 0x7f3ca54b9158>
  pre_exec: <function PreExec.pre_exec at 0x7f3ca54b9268>
  pre_request: <function PreRequest.pre_request at 0x7f3ca54b9378>
  post_request: <function PostRequest.post_request at 0x7f3ca54b9400>
  child_exit: <function ChildExit.child_exit at 0x7f3ca54b9510>
  worker_exit: <function WorkerExit.worker_exit at 0x7f3ca54b9620>
  nworkers_changed: <function NumWorkersChanged.nworkers_changed at 0x7f3ca54b9730>
  on_exit: <function OnExit.on_exit at 0x7f3ca54b9840>
  proxy_protocol: False
  proxy_allow_ips: ['127.0.0.1']
  keyfile: None
  certfile: None
  ssl_version: 2
  cert_reqs: 0
  ca_certs: None
  suppress_ragged_eofs: True
  do_handshake_on_connect: False
  ciphers: TLSv1
  raw_paste_global_conf: []
[2019-07-01 16:35:49 +0000] [18413] [INFO] Starting gunicorn 19.9.0
[2019-07-01 16:35:49 +0000] [18413] [DEBUG] Arbiter booted
[2019-07-01 16:35:49 +0000] [18413] [INFO] Listening at: unix:/home/ubuntu/workspace/spoti_env/run/gunicorn.sock (18413)
[2019-07-01 16:35:49 +0000] [18413] [INFO] Using worker: sync
[2019-07-01 16:35:49 +0000] [18416] [INFO] Booting worker with pid: 18416
[2019-07-01 16:35:50 +0000] [18418] [INFO] Booting worker with pid: 18418
[2019-07-01 16:35:50 +0000] [18419] [INFO] Booting worker with pid: 18419
[2019-07-01 16:35:50 +0000] [18413] [DEBUG] 3 workers
[2019-07-01 16:35:50 +0000] [18416] [ERROR] Exception in worker process
Traceback (most recent call last):
  File "/home/ubuntu/workspace/spoti_env/lib/python3.6/site-packages/gunicorn/arbiter.py", line 583, in spawn_worker
    worker.init_process()
  File "/home/ubuntu/workspace/spoti_env/lib/python3.6/site-packages/gunicorn/workers/base.py", line 129, in init_process
    self.load_wsgi()
  File "/home/ubuntu/workspace/spoti_env/lib/python3.6/site-packages/gunicorn/workers/base.py", line 138, in load_wsgi
    self.wsgi = self.app.wsgi()
  File "/home/ubuntu/workspace/spoti_env/lib/python3.6/site-packages/gunicorn/app/base.py", line 67, in wsgi
    self.callable = self.load()
  File "/home/ubuntu/workspace/spoti_env/lib/python3.6/site-packages/gunicorn/app/wsgiapp.py", line 52, in load
    return self.load_wsgiapp()
  File "/home/ubuntu/workspace/spoti_env/lib/python3.6/site-packages/gunicorn/app/wsgiapp.py", line 41, in load_wsgiapp
    return util.import_app(self.app_uri)
  File "/home/ubuntu/workspace/spoti_env/lib/python3.6/site-packages/gunicorn/util.py", line 350, in import_app
    __import__(module)
  File "/home/ubuntu/workspace/spoti_env/spotifollow/spotifollow/spotifollow/wsgi.py", line 16, in <module>
    application = get_wsgi_application()
  File "/home/ubuntu/workspace/spoti_env/lib/python3.6/site-packages/django/core/wsgi.py", line 12, in get_wsgi_application
    django.setup(set_prefix=False)
  File "/home/ubuntu/workspace/spoti_env/lib/python3.6/site-packages/django/__init__.py", line 19, in setup
    configure_logging(settings.LOGGING_CONFIG, settings.LOGGING)
  File "/home/ubuntu/workspace/spoti_env/lib/python3.6/site-packages/django/conf/__init__.py", line 79, in __getattr__
    self._setup(name)
  File "/home/ubuntu/workspace/spoti_env/lib/python3.6/site-packages/django/conf/__init__.py", line 66, in _setup
    self._wrapped = Settings(settings_module)
  File "/home/ubuntu/workspace/spoti_env/lib/python3.6/site-packages/django/conf/__init__.py", line 176, in __init__
    raise ImproperlyConfigured("The SECRET_KEY setting must not be empty.")
django.core.exceptions.ImproperlyConfigured: The SECRET_KEY setting must not be empty.
[2019-07-01 16:35:50 +0000] [18416] [INFO] Worker exiting (pid: 18416)
[2019-07-01 16:35:50 +0000] [18418] [ERROR] Exception in worker process
Traceback (most recent call last):
  File "/home/ubuntu/workspace/spoti_env/lib/python3.6/site-packages/gunicorn/arbiter.py", line 583, in spawn_worker
    worker.init_process()
  File "/home/ubuntu/workspace/spoti_env/lib/python3.6/site-packages/gunicorn/workers/base.py", line 129, in init_process
    self.load_wsgi()
  File "/home/ubuntu/workspace/spoti_env/lib/python3.6/site-packages/gunicorn/workers/base.py", line 138, in load_wsgi
    self.wsgi = self.app.wsgi()
  File "/home/ubuntu/workspace/spoti_env/lib/python3.6/site-packages/gunicorn/app/base.py", line 67, in wsgi
    self.callable = self.load()
  File "/home/ubuntu/workspace/spoti_env/lib/python3.6/site-packages/gunicorn/app/wsgiapp.py", line 52, in load
    return self.load_wsgiapp()
  File "/home/ubuntu/workspace/spoti_env/lib/python3.6/site-packages/gunicorn/app/wsgiapp.py", line 41, in load_wsgiapp
    return util.import_app(self.app_uri)
  File "/home/ubuntu/workspace/spoti_env/lib/python3.6/site-packages/gunicorn/util.py", line 350, in import_app
    __import__(module)
  File "/home/ubuntu/workspace/spoti_env/spotifollow/spotifollow/spotifollow/wsgi.py", line 16, in <module>
    application = get_wsgi_application()
  File "/home/ubuntu/workspace/spoti_env/lib/python3.6/site-packages/django/core/wsgi.py", line 12, in get_wsgi_application
    django.setup(set_prefix=False)
  File "/home/ubuntu/workspace/spoti_env/lib/python3.6/site-packages/django/__init__.py", line 19, in setup
    configure_logging(settings.LOGGING_CONFIG, settings.LOGGING)
  File "/home/ubuntu/workspace/spoti_env/lib/python3.6/site-packages/django/conf/__init__.py", line 79, in __getattr__
    self._setup(name)
  File "/home/ubuntu/workspace/spoti_env/lib/python3.6/site-packages/django/conf/__init__.py", line 66, in _setup
    self._wrapped = Settings(settings_module)
  File "/home/ubuntu/workspace/spoti_env/lib/python3.6/site-packages/django/conf/__init__.py", line 176, in __init__
    raise ImproperlyConfigured("The SECRET_KEY setting must not be empty.")
django.core.exceptions.ImproperlyConfigured: The SECRET_KEY setting must not be empty.
[2019-07-01 16:35:50 +0000] [18418] [INFO] Worker exiting (pid: 18418)
[2019-07-01 16:35:50 +0000] [18419] [ERROR] Exception in worker process
Traceback (most recent call last):
  File "/home/ubuntu/workspace/spoti_env/lib/python3.6/site-packages/gunicorn/arbiter.py", line 583, in spawn_worker
    worker.init_process()
  File "/home/ubuntu/workspace/spoti_env/lib/python3.6/site-packages/gunicorn/workers/base.py", line 129, in init_process
    self.load_wsgi()
  File "/home/ubuntu/workspace/spoti_env/lib/python3.6/site-packages/gunicorn/workers/base.py", line 138, in load_wsgi
    self.wsgi = self.app.wsgi()
  File "/home/ubuntu/workspace/spoti_env/lib/python3.6/site-packages/gunicorn/app/base.py", line 67, in wsgi
    self.callable = self.load()
  File "/home/ubuntu/workspace/spoti_env/lib/python3.6/site-packages/gunicorn/app/wsgiapp.py", line 52, in load
    return self.load_wsgiapp()
  File "/home/ubuntu/workspace/spoti_env/lib/python3.6/site-packages/gunicorn/app/wsgiapp.py", line 41, in load_wsgiapp
    return util.import_app(self.app_uri)
  File "/home/ubuntu/workspace/spoti_env/lib/python3.6/site-packages/gunicorn/util.py", line 350, in import_app
    __import__(module)
  File "/home/ubuntu/workspace/spoti_env/spotifollow/spotifollow/spotifollow/wsgi.py", line 16, in <module>
    application = get_wsgi_application()
  File "/home/ubuntu/workspace/spoti_env/lib/python3.6/site-packages/django/core/wsgi.py", line 12, in get_wsgi_application
    django.setup(set_prefix=False)
  File "/home/ubuntu/workspace/spoti_env/lib/python3.6/site-packages/django/__init__.py", line 19, in setup
    configure_logging(settings.LOGGING_CONFIG, settings.LOGGING)
  File "/home/ubuntu/workspace/spoti_env/lib/python3.6/site-packages/django/conf/__init__.py", line 79, in __getattr__
    self._setup(name)
  File "/home/ubuntu/workspace/spoti_env/lib/python3.6/site-packages/django/conf/__init__.py", line 66, in _setup
    self._wrapped = Settings(settings_module)
  File "/home/ubuntu/workspace/spoti_env/lib/python3.6/site-packages/django/conf/__init__.py", line 176, in __init__
    raise ImproperlyConfigured("The SECRET_KEY setting must not be empty.")
django.core.exceptions.ImproperlyConfigured: The SECRET_KEY setting must not be empty.
[2019-07-01 16:35:50 +0000] [18419] [INFO] Worker exiting (pid: 18419)
Traceback (most recent call last):
  File "/home/ubuntu/workspace/spoti_env/lib/python3.6/site-packages/gunicorn/arbiter.py", line 210, in run
    self.sleep()
  File "/home/ubuntu/workspace/spoti_env/lib/python3.6/site-packages/gunicorn/arbiter.py", line 360, in sleep
    ready = select.select([self.PIPE[0]], [], [], 1.0)
  File "/home/ubuntu/workspace/spoti_env/lib/python3.6/site-packages/gunicorn/arbiter.py", line 245, in handle_chld
    self.reap_workers()
  File "/home/ubuntu/workspace/spoti_env/lib/python3.6/site-packages/gunicorn/arbiter.py", line 525, in reap_workers
    raise HaltServer(reason, self.WORKER_BOOT_ERROR)
gunicorn.errors.HaltServer: <HaltServer 'Worker failed to boot.' 3>

During handling of the above exception, another exception occurred:

Traceback (most recent call last):
  File "/home/ubuntu/workspace/spoti_env/spotifollow/spotifollow/../../bin/gunicorn", line 10, in <module>
    sys.exit(run())
  File "/home/ubuntu/workspace/spoti_env/lib/python3.6/site-packages/gunicorn/app/wsgiapp.py", line 61, in run
    WSGIApplication("%(prog)s [OPTIONS] [APP_MODULE]").run()
  File "/home/ubuntu/workspace/spoti_env/lib/python3.6/site-packages/gunicorn/app/base.py", line 223, in run
    super(Application, self).run()
  File "/home/ubuntu/workspace/spoti_env/lib/python3.6/site-packages/gunicorn/app/base.py", line 72, in run
    Arbiter(self).run()
  File "/home/ubuntu/workspace/spoti_env/lib/python3.6/site-packages/gunicorn/arbiter.py", line 232, in run
    self.halt(reason=inst.reason, exit_status=inst.exit_status)
  File "/home/ubuntu/workspace/spoti_env/lib/python3.6/site-packages/gunicorn/arbiter.py", line 345, in halt
    self.stop()
  File "/home/ubuntu/workspace/spoti_env/lib/python3.6/site-packages/gunicorn/arbiter.py", line 393, in stop
    time.sleep(0.1)
  File "/home/ubuntu/workspace/spoti_env/lib/python3.6/site-packages/gunicorn/arbiter.py", line 245, in handle_chld
    self.reap_workers()
  File "/home/ubuntu/workspace/spoti_env/lib/python3.6/site-packages/gunicorn/arbiter.py", line 525, in reap_workers
    raise HaltServer(reason, self.WORKER_BOOT_ERROR)
gunicorn.errors.HaltServer: <HaltServer 'Worker failed to boot.' 3>
[2019-07-01 16:36:59 +0000] [18435] [DEBUG] Current configuration:
  config: None
  bind: ['unix:/home/ubuntu/workspace/spoti_env/run/gunicorn.sock']
  backlog: 2048
  workers: 3
  worker_class: sync
  threads: 1
  worker_connections: 1000
  max_requests: 0
  max_requests_jitter: 0
  timeout: 30
  graceful_timeout: 30
  keepalive: 2
  limit_request_line: 4094
  limit_request_fields: 100
  limit_request_field_size: 8190
  reload: False
  reload_engine: auto
  reload_extra_files: []
  spew: False
  check_config: False
  preload_app: False
  sendfile: None
  reuse_port: False
  chdir: /home/ubuntu/workspace/spoti_env/spotifollow/spotifollow
  daemon: False
  raw_env: []
  pidfile: None
  worker_tmp_dir: None
  user: 998
  group: 998
  umask: 0
  initgroups: False
  tmp_upload_dir: None
  secure_scheme_headers: {'X-FORWARDED-PROTOCOL': 'ssl', 'X-FORWARDED-PROTO': 'https', 'X-FORWARDED-SSL': 'on'}
  forwarded_allow_ips: ['127.0.0.1']
  accesslog: None
  disable_redirect_access_to_syslog: False
  access_log_format: %(h)s %(l)s %(u)s %(t)s "%(r)s" %(s)s %(b)s "%(f)s" "%(a)s"
  errorlog: /home/ubuntu/workspace/spoti_env/spotifollow/spotifollow/spotifollow.log
  loglevel: debug
  capture_output: False
  logger_class: gunicorn.glogging.Logger
  logconfig: None
  logconfig_dict: {}
  syslog_addr: udp://localhost:514
  syslog: False
  syslog_prefix: None
  syslog_facility: user
  enable_stdio_inheritance: False
  statsd_host: None
  statsd_prefix: 
  proc_name: spotifollow_app
  default_proc_name: spotifollow.wsgi:application
  pythonpath: None
  paste: None
  on_starting: <function OnStarting.on_starting at 0x7f46a189f950>
  on_reload: <function OnReload.on_reload at 0x7f46a189fa60>
  when_ready: <function WhenReady.when_ready at 0x7f46a189fb70>
  pre_fork: <function Prefork.pre_fork at 0x7f46a189fc80>
  post_fork: <function Postfork.post_fork at 0x7f46a189fd90>
  post_worker_init: <function PostWorkerInit.post_worker_init at 0x7f46a189fea0>
  worker_int: <function WorkerInt.worker_int at 0x7f46a13af048>
  worker_abort: <function WorkerAbort.worker_abort at 0x7f46a13af158>
  pre_exec: <function PreExec.pre_exec at 0x7f46a13af268>
  pre_request: <function PreRequest.pre_request at 0x7f46a13af378>
  post_request: <function PostRequest.post_request at 0x7f46a13af400>
  child_exit: <function ChildExit.child_exit at 0x7f46a13af510>
  worker_exit: <function WorkerExit.worker_exit at 0x7f46a13af620>
  nworkers_changed: <function NumWorkersChanged.nworkers_changed at 0x7f46a13af730>
  on_exit: <function OnExit.on_exit at 0x7f46a13af840>
  proxy_protocol: False
  proxy_allow_ips: ['127.0.0.1']
  keyfile: None
  certfile: None
  ssl_version: 2
  cert_reqs: 0
  ca_certs: None
  suppress_ragged_eofs: True
  do_handshake_on_connect: False
  ciphers: TLSv1
  raw_paste_global_conf: []
[2019-07-01 16:36:59 +0000] [18435] [INFO] Starting gunicorn 19.9.0
[2019-07-01 16:36:59 +0000] [18435] [DEBUG] Arbiter booted
[2019-07-01 16:36:59 +0000] [18435] [INFO] Listening at: unix:/home/ubuntu/workspace/spoti_env/run/gunicorn.sock (18435)
[2019-07-01 16:36:59 +0000] [18435] [INFO] Using worker: sync
[2019-07-01 16:36:59 +0000] [18438] [INFO] Booting worker with pid: 18438
[2019-07-01 16:36:59 +0000] [18439] [INFO] Booting worker with pid: 18439
[2019-07-01 16:36:59 +0000] [18440] [INFO] Booting worker with pid: 18440
[2019-07-01 16:36:59 +0000] [18435] [DEBUG] 3 workers
[2019-07-01 16:36:59 +0000] [18438] [ERROR] Exception in worker process
Traceback (most recent call last):
  File "/home/ubuntu/workspace/spoti_env/lib/python3.6/site-packages/gunicorn/arbiter.py", line 583, in spawn_worker
    worker.init_process()
  File "/home/ubuntu/workspace/spoti_env/lib/python3.6/site-packages/gunicorn/workers/base.py", line 129, in init_process
    self.load_wsgi()
  File "/home/ubuntu/workspace/spoti_env/lib/python3.6/site-packages/gunicorn/workers/base.py", line 138, in load_wsgi
    self.wsgi = self.app.wsgi()
  File "/home/ubuntu/workspace/spoti_env/lib/python3.6/site-packages/gunicorn/app/base.py", line 67, in wsgi
    self.callable = self.load()
  File "/home/ubuntu/workspace/spoti_env/lib/python3.6/site-packages/gunicorn/app/wsgiapp.py", line 52, in load
    return self.load_wsgiapp()
  File "/home/ubuntu/workspace/spoti_env/lib/python3.6/site-packages/gunicorn/app/wsgiapp.py", line 41, in load_wsgiapp
    return util.import_app(self.app_uri)
  File "/home/ubuntu/workspace/spoti_env/lib/python3.6/site-packages/gunicorn/util.py", line 350, in import_app
    __import__(module)
  File "/home/ubuntu/workspace/spoti_env/spotifollow/spotifollow/spotifollow/wsgi.py", line 16, in <module>
    application = get_wsgi_application()
  File "/home/ubuntu/workspace/spoti_env/lib/python3.6/site-packages/django/core/wsgi.py", line 12, in get_wsgi_application
    django.setup(set_prefix=False)
  File "/home/ubuntu/workspace/spoti_env/lib/python3.6/site-packages/django/__init__.py", line 19, in setup
    configure_logging(settings.LOGGING_CONFIG, settings.LOGGING)
  File "/home/ubuntu/workspace/spoti_env/lib/python3.6/site-packages/django/conf/__init__.py", line 79, in __getattr__
    self._setup(name)
  File "/home/ubuntu/workspace/spoti_env/lib/python3.6/site-packages/django/conf/__init__.py", line 66, in _setup
    self._wrapped = Settings(settings_module)
  File "/home/ubuntu/workspace/spoti_env/lib/python3.6/site-packages/django/conf/__init__.py", line 176, in __init__
    raise ImproperlyConfigured("The SECRET_KEY setting must not be empty.")
django.core.exceptions.ImproperlyConfigured: The SECRET_KEY setting must not be empty.
[2019-07-01 16:36:59 +0000] [18438] [INFO] Worker exiting (pid: 18438)
[2019-07-01 16:36:59 +0000] [18439] [ERROR] Exception in worker process
Traceback (most recent call last):
  File "/home/ubuntu/workspace/spoti_env/lib/python3.6/site-packages/gunicorn/arbiter.py", line 583, in spawn_worker
    worker.init_process()
  File "/home/ubuntu/workspace/spoti_env/lib/python3.6/site-packages/gunicorn/workers/base.py", line 129, in init_process
    self.load_wsgi()
  File "/home/ubuntu/workspace/spoti_env/lib/python3.6/site-packages/gunicorn/workers/base.py", line 138, in load_wsgi
    self.wsgi = self.app.wsgi()
  File "/home/ubuntu/workspace/spoti_env/lib/python3.6/site-packages/gunicorn/app/base.py", line 67, in wsgi
    self.callable = self.load()
  File "/home/ubuntu/workspace/spoti_env/lib/python3.6/site-packages/gunicorn/app/wsgiapp.py", line 52, in load
    return self.load_wsgiapp()
  File "/home/ubuntu/workspace/spoti_env/lib/python3.6/site-packages/gunicorn/app/wsgiapp.py", line 41, in load_wsgiapp
    return util.import_app(self.app_uri)
  File "/home/ubuntu/workspace/spoti_env/lib/python3.6/site-packages/gunicorn/util.py", line 350, in import_app
    __import__(module)
  File "/home/ubuntu/workspace/spoti_env/spotifollow/spotifollow/spotifollow/wsgi.py", line 16, in <module>
    application = get_wsgi_application()
  File "/home/ubuntu/workspace/spoti_env/lib/python3.6/site-packages/django/core/wsgi.py", line 12, in get_wsgi_application
    django.setup(set_prefix=False)
  File "/home/ubuntu/workspace/spoti_env/lib/python3.6/site-packages/django/__init__.py", line 19, in setup
    configure_logging(settings.LOGGING_CONFIG, settings.LOGGING)
  File "/home/ubuntu/workspace/spoti_env/lib/python3.6/site-packages/django/conf/__init__.py", line 79, in __getattr__
    self._setup(name)
  File "/home/ubuntu/workspace/spoti_env/lib/python3.6/site-packages/django/conf/__init__.py", line 66, in _setup
    self._wrapped = Settings(settings_module)
  File "/home/ubuntu/workspace/spoti_env/lib/python3.6/site-packages/django/conf/__init__.py", line 176, in __init__
    raise ImproperlyConfigured("The SECRET_KEY setting must not be empty.")
django.core.exceptions.ImproperlyConfigured: The SECRET_KEY setting must not be empty.
[2019-07-01 16:36:59 +0000] [18439] [INFO] Worker exiting (pid: 18439)
[2019-07-01 16:36:59 +0000] [18440] [ERROR] Exception in worker process
Traceback (most recent call last):
  File "/home/ubuntu/workspace/spoti_env/lib/python3.6/site-packages/gunicorn/arbiter.py", line 583, in spawn_worker
    worker.init_process()
  File "/home/ubuntu/workspace/spoti_env/lib/python3.6/site-packages/gunicorn/workers/base.py", line 129, in init_process
    self.load_wsgi()
  File "/home/ubuntu/workspace/spoti_env/lib/python3.6/site-packages/gunicorn/workers/base.py", line 138, in load_wsgi
    self.wsgi = self.app.wsgi()
  File "/home/ubuntu/workspace/spoti_env/lib/python3.6/site-packages/gunicorn/app/base.py", line 67, in wsgi
    self.callable = self.load()
  File "/home/ubuntu/workspace/spoti_env/lib/python3.6/site-packages/gunicorn/app/wsgiapp.py", line 52, in load
    return self.load_wsgiapp()
  File "/home/ubuntu/workspace/spoti_env/lib/python3.6/site-packages/gunicorn/app/wsgiapp.py", line 41, in load_wsgiapp
    return util.import_app(self.app_uri)
  File "/home/ubuntu/workspace/spoti_env/lib/python3.6/site-packages/gunicorn/util.py", line 350, in import_app
    __import__(module)
  File "/home/ubuntu/workspace/spoti_env/spotifollow/spotifollow/spotifollow/wsgi.py", line 16, in <module>
    application = get_wsgi_application()
  File "/home/ubuntu/workspace/spoti_env/lib/python3.6/site-packages/django/core/wsgi.py", line 12, in get_wsgi_application
    django.setup(set_prefix=False)
  File "/home/ubuntu/workspace/spoti_env/lib/python3.6/site-packages/django/__init__.py", line 19, in setup
    configure_logging(settings.LOGGING_CONFIG, settings.LOGGING)
  File "/home/ubuntu/workspace/spoti_env/lib/python3.6/site-packages/django/conf/__init__.py", line 79, in __getattr__
    self._setup(name)
  File "/home/ubuntu/workspace/spoti_env/lib/python3.6/site-packages/django/conf/__init__.py", line 66, in _setup
    self._wrapped = Settings(settings_module)
  File "/home/ubuntu/workspace/spoti_env/lib/python3.6/site-packages/django/conf/__init__.py", line 176, in __init__
    raise ImproperlyConfigured("The SECRET_KEY setting must not be empty.")
django.core.exceptions.ImproperlyConfigured: The SECRET_KEY setting must not be empty.
[2019-07-01 16:36:59 +0000] [18440] [INFO] Worker exiting (pid: 18440)
Traceback (most recent call last):
  File "/home/ubuntu/workspace/spoti_env/lib/python3.6/site-packages/gunicorn/arbiter.py", line 210, in run
    self.sleep()
  File "/home/ubuntu/workspace/spoti_env/lib/python3.6/site-packages/gunicorn/arbiter.py", line 360, in sleep
    ready = select.select([self.PIPE[0]], [], [], 1.0)
  File "/home/ubuntu/workspace/spoti_env/lib/python3.6/site-packages/gunicorn/arbiter.py", line 245, in handle_chld
    self.reap_workers()
  File "/home/ubuntu/workspace/spoti_env/lib/python3.6/site-packages/gunicorn/arbiter.py", line 525, in reap_workers
    raise HaltServer(reason, self.WORKER_BOOT_ERROR)
gunicorn.errors.HaltServer: <HaltServer 'Worker failed to boot.' 3>

During handling of the above exception, another exception occurred:

Traceback (most recent call last):
  File "/home/ubuntu/workspace/spoti_env/spotifollow/spotifollow/../../bin/gunicorn", line 10, in <module>
    sys.exit(run())
  File "/home/ubuntu/workspace/spoti_env/lib/python3.6/site-packages/gunicorn/app/wsgiapp.py", line 61, in run
    WSGIApplication("%(prog)s [OPTIONS] [APP_MODULE]").run()
  File "/home/ubuntu/workspace/spoti_env/lib/python3.6/site-packages/gunicorn/app/base.py", line 223, in run
    super(Application, self).run()
  File "/home/ubuntu/workspace/spoti_env/lib/python3.6/site-packages/gunicorn/app/base.py", line 72, in run
    Arbiter(self).run()
  File "/home/ubuntu/workspace/spoti_env/lib/python3.6/site-packages/gunicorn/arbiter.py", line 232, in run
    self.halt(reason=inst.reason, exit_status=inst.exit_status)
  File "/home/ubuntu/workspace/spoti_env/lib/python3.6/site-packages/gunicorn/arbiter.py", line 345, in halt
    self.stop()
  File "/home/ubuntu/workspace/spoti_env/lib/python3.6/site-packages/gunicorn/arbiter.py", line 393, in stop
    time.sleep(0.1)
  File "/home/ubuntu/workspace/spoti_env/lib/python3.6/site-packages/gunicorn/arbiter.py", line 245, in handle_chld
    self.reap_workers()
  File "/home/ubuntu/workspace/spoti_env/lib/python3.6/site-packages/gunicorn/arbiter.py", line 525, in reap_workers
    raise HaltServer(reason, self.WORKER_BOOT_ERROR)
gunicorn.errors.HaltServer: <HaltServer 'Worker failed to boot.' 3>
[2019-07-01 16:37:51 +0000] [18478] [DEBUG] Current configuration:
  config: None
  bind: ['unix:/home/ubuntu/workspace/spoti_env/run/gunicorn.sock']
  backlog: 2048
  workers: 3
  worker_class: sync
  threads: 1
  worker_connections: 1000
  max_requests: 0
  max_requests_jitter: 0
  timeout: 30
  graceful_timeout: 30
  keepalive: 2
  limit_request_line: 4094
  limit_request_fields: 100
  limit_request_field_size: 8190
  reload: False
  reload_engine: auto
  reload_extra_files: []
  spew: False
  check_config: False
  preload_app: False
  sendfile: None
  reuse_port: False
  chdir: /home/ubuntu/workspace/spoti_env/spotifollow/spotifollow
  daemon: False
  raw_env: []
  pidfile: None
  worker_tmp_dir: None
  user: 998
  group: 998
  umask: 0
  initgroups: False
  tmp_upload_dir: None
  secure_scheme_headers: {'X-FORWARDED-PROTOCOL': 'ssl', 'X-FORWARDED-PROTO': 'https', 'X-FORWARDED-SSL': 'on'}
  forwarded_allow_ips: ['127.0.0.1']
  accesslog: None
  disable_redirect_access_to_syslog: False
  access_log_format: %(h)s %(l)s %(u)s %(t)s "%(r)s" %(s)s %(b)s "%(f)s" "%(a)s"
  errorlog: /home/ubuntu/workspace/spoti_env/spotifollow/spotifollow/spotifollow.log
  loglevel: debug
  capture_output: False
  logger_class: gunicorn.glogging.Logger
  logconfig: None
  logconfig_dict: {}
  syslog_addr: udp://localhost:514
  syslog: False
  syslog_prefix: None
  syslog_facility: user
  enable_stdio_inheritance: False
  statsd_host: None
  statsd_prefix: 
  proc_name: spotifollow_app
  default_proc_name: spotifollow.wsgi:application
  pythonpath: None
  paste: None
  on_starting: <function OnStarting.on_starting at 0x7fd72658b950>
  on_reload: <function OnReload.on_reload at 0x7fd72658ba60>
  when_ready: <function WhenReady.when_ready at 0x7fd72658bb70>
  pre_fork: <function Prefork.pre_fork at 0x7fd72658bc80>
  post_fork: <function Postfork.post_fork at 0x7fd72658bd90>
  post_worker_init: <function PostWorkerInit.post_worker_init at 0x7fd72658bea0>
  worker_int: <function WorkerInt.worker_int at 0x7fd72609b048>
  worker_abort: <function WorkerAbort.worker_abort at 0x7fd72609b158>
  pre_exec: <function PreExec.pre_exec at 0x7fd72609b268>
  pre_request: <function PreRequest.pre_request at 0x7fd72609b378>
  post_request: <function PostRequest.post_request at 0x7fd72609b400>
  child_exit: <function ChildExit.child_exit at 0x7fd72609b510>
  worker_exit: <function WorkerExit.worker_exit at 0x7fd72609b620>
  nworkers_changed: <function NumWorkersChanged.nworkers_changed at 0x7fd72609b730>
  on_exit: <function OnExit.on_exit at 0x7fd72609b840>
  proxy_protocol: False
  proxy_allow_ips: ['127.0.0.1']
  keyfile: None
  certfile: None
  ssl_version: 2
  cert_reqs: 0
  ca_certs: None
  suppress_ragged_eofs: True
  do_handshake_on_connect: False
  ciphers: TLSv1
  raw_paste_global_conf: []
[2019-07-01 16:37:51 +0000] [18478] [INFO] Starting gunicorn 19.9.0
[2019-07-01 16:37:51 +0000] [18478] [DEBUG] Arbiter booted
[2019-07-01 16:37:51 +0000] [18478] [INFO] Listening at: unix:/home/ubuntu/workspace/spoti_env/run/gunicorn.sock (18478)
[2019-07-01 16:37:51 +0000] [18478] [INFO] Using worker: sync
[2019-07-01 16:37:51 +0000] [18481] [INFO] Booting worker with pid: 18481
[2019-07-01 16:37:51 +0000] [18482] [INFO] Booting worker with pid: 18482
[2019-07-01 16:37:51 +0000] [18483] [INFO] Booting worker with pid: 18483
[2019-07-01 16:37:51 +0000] [18478] [DEBUG] 3 workers
[2019-07-01 16:37:51 +0000] [18481] [ERROR] Exception in worker process
Traceback (most recent call last):
  File "/home/ubuntu/workspace/spoti_env/lib/python3.6/site-packages/gunicorn/arbiter.py", line 583, in spawn_worker
    worker.init_process()
  File "/home/ubuntu/workspace/spoti_env/lib/python3.6/site-packages/gunicorn/workers/base.py", line 129, in init_process
    self.load_wsgi()
  File "/home/ubuntu/workspace/spoti_env/lib/python3.6/site-packages/gunicorn/workers/base.py", line 138, in load_wsgi
    self.wsgi = self.app.wsgi()
  File "/home/ubuntu/workspace/spoti_env/lib/python3.6/site-packages/gunicorn/app/base.py", line 67, in wsgi
    self.callable = self.load()
  File "/home/ubuntu/workspace/spoti_env/lib/python3.6/site-packages/gunicorn/app/wsgiapp.py", line 52, in load
    return self.load_wsgiapp()
  File "/home/ubuntu/workspace/spoti_env/lib/python3.6/site-packages/gunicorn/app/wsgiapp.py", line 41, in load_wsgiapp
    return util.import_app(self.app_uri)
  File "/home/ubuntu/workspace/spoti_env/lib/python3.6/site-packages/gunicorn/util.py", line 350, in import_app
    __import__(module)
  File "/home/ubuntu/workspace/spoti_env/spotifollow/spotifollow/spotifollow/wsgi.py", line 16, in <module>
    application = get_wsgi_application()
  File "/home/ubuntu/workspace/spoti_env/lib/python3.6/site-packages/django/core/wsgi.py", line 12, in get_wsgi_application
    django.setup(set_prefix=False)
  File "/home/ubuntu/workspace/spoti_env/lib/python3.6/site-packages/django/__init__.py", line 19, in setup
    configure_logging(settings.LOGGING_CONFIG, settings.LOGGING)
  File "/home/ubuntu/workspace/spoti_env/lib/python3.6/site-packages/django/conf/__init__.py", line 79, in __getattr__
    self._setup(name)
  File "/home/ubuntu/workspace/spoti_env/lib/python3.6/site-packages/django/conf/__init__.py", line 66, in _setup
    self._wrapped = Settings(settings_module)
  File "/home/ubuntu/workspace/spoti_env/lib/python3.6/site-packages/django/conf/__init__.py", line 176, in __init__
    raise ImproperlyConfigured("The SECRET_KEY setting must not be empty.")
django.core.exceptions.ImproperlyConfigured: The SECRET_KEY setting must not be empty.
[2019-07-01 16:37:51 +0000] [18481] [INFO] Worker exiting (pid: 18481)
[2019-07-01 16:37:51 +0000] [18482] [ERROR] Exception in worker process
Traceback (most recent call last):
  File "/home/ubuntu/workspace/spoti_env/lib/python3.6/site-packages/gunicorn/arbiter.py", line 583, in spawn_worker
    worker.init_process()
  File "/home/ubuntu/workspace/spoti_env/lib/python3.6/site-packages/gunicorn/workers/base.py", line 129, in init_process
    self.load_wsgi()
  File "/home/ubuntu/workspace/spoti_env/lib/python3.6/site-packages/gunicorn/workers/base.py", line 138, in load_wsgi
    self.wsgi = self.app.wsgi()
  File "/home/ubuntu/workspace/spoti_env/lib/python3.6/site-packages/gunicorn/app/base.py", line 67, in wsgi
    self.callable = self.load()
  File "/home/ubuntu/workspace/spoti_env/lib/python3.6/site-packages/gunicorn/app/wsgiapp.py", line 52, in load
    return self.load_wsgiapp()
  File "/home/ubuntu/workspace/spoti_env/lib/python3.6/site-packages/gunicorn/app/wsgiapp.py", line 41, in load_wsgiapp
    return util.import_app(self.app_uri)
  File "/home/ubuntu/workspace/spoti_env/lib/python3.6/site-packages/gunicorn/util.py", line 350, in import_app
    __import__(module)
  File "/home/ubuntu/workspace/spoti_env/spotifollow/spotifollow/spotifollow/wsgi.py", line 16, in <module>
    application = get_wsgi_application()
  File "/home/ubuntu/workspace/spoti_env/lib/python3.6/site-packages/django/core/wsgi.py", line 12, in get_wsgi_application
    django.setup(set_prefix=False)
  File "/home/ubuntu/workspace/spoti_env/lib/python3.6/site-packages/django/__init__.py", line 19, in setup
    configure_logging(settings.LOGGING_CONFIG, settings.LOGGING)
  File "/home/ubuntu/workspace/spoti_env/lib/python3.6/site-packages/django/conf/__init__.py", line 79, in __getattr__
    self._setup(name)
  File "/home/ubuntu/workspace/spoti_env/lib/python3.6/site-packages/django/conf/__init__.py", line 66, in _setup
    self._wrapped = Settings(settings_module)
  File "/home/ubuntu/workspace/spoti_env/lib/python3.6/site-packages/django/conf/__init__.py", line 176, in __init__
    raise ImproperlyConfigured("The SECRET_KEY setting must not be empty.")
django.core.exceptions.ImproperlyConfigured: The SECRET_KEY setting must not be empty.
[2019-07-01 16:37:51 +0000] [18482] [INFO] Worker exiting (pid: 18482)
[2019-07-01 16:37:51 +0000] [18483] [ERROR] Exception in worker process
Traceback (most recent call last):
  File "/home/ubuntu/workspace/spoti_env/lib/python3.6/site-packages/gunicorn/arbiter.py", line 583, in spawn_worker
    worker.init_process()
  File "/home/ubuntu/workspace/spoti_env/lib/python3.6/site-packages/gunicorn/workers/base.py", line 129, in init_process
    self.load_wsgi()
  File "/home/ubuntu/workspace/spoti_env/lib/python3.6/site-packages/gunicorn/workers/base.py", line 138, in load_wsgi
    self.wsgi = self.app.wsgi()
  File "/home/ubuntu/workspace/spoti_env/lib/python3.6/site-packages/gunicorn/app/base.py", line 67, in wsgi
    self.callable = self.load()
  File "/home/ubuntu/workspace/spoti_env/lib/python3.6/site-packages/gunicorn/app/wsgiapp.py", line 52, in load
    return self.load_wsgiapp()
  File "/home/ubuntu/workspace/spoti_env/lib/python3.6/site-packages/gunicorn/app/wsgiapp.py", line 41, in load_wsgiapp
    return util.import_app(self.app_uri)
  File "/home/ubuntu/workspace/spoti_env/lib/python3.6/site-packages/gunicorn/util.py", line 350, in import_app
    __import__(module)
  File "/home/ubuntu/workspace/spoti_env/spotifollow/spotifollow/spotifollow/wsgi.py", line 16, in <module>
    application = get_wsgi_application()
  File "/home/ubuntu/workspace/spoti_env/lib/python3.6/site-packages/django/core/wsgi.py", line 12, in get_wsgi_application
    django.setup(set_prefix=False)
  File "/home/ubuntu/workspace/spoti_env/lib/python3.6/site-packages/django/__init__.py", line 19, in setup
    configure_logging(settings.LOGGING_CONFIG, settings.LOGGING)
  File "/home/ubuntu/workspace/spoti_env/lib/python3.6/site-packages/django/conf/__init__.py", line 79, in __getattr__
    self._setup(name)
  File "/home/ubuntu/workspace/spoti_env/lib/python3.6/site-packages/django/conf/__init__.py", line 66, in _setup
    self._wrapped = Settings(settings_module)
  File "/home/ubuntu/workspace/spoti_env/lib/python3.6/site-packages/django/conf/__init__.py", line 176, in __init__
    raise ImproperlyConfigured("The SECRET_KEY setting must not be empty.")
django.core.exceptions.ImproperlyConfigured: The SECRET_KEY setting must not be empty.
[2019-07-01 16:37:51 +0000] [18483] [INFO] Worker exiting (pid: 18483)
[2019-07-01 16:37:51 +0000] [18478] [INFO] Shutting down: Master
[2019-07-01 16:37:51 +0000] [18478] [INFO] Reason: Worker failed to boot.
[2019-07-01 16:39:13 +0000] [18502] [DEBUG] Current configuration:
  config: None
  bind: ['unix:/home/ubuntu/workspace/spoti_env/run/gunicorn.sock']
  backlog: 2048
  workers: 3
  worker_class: sync
  threads: 1
  worker_connections: 1000
  max_requests: 0
  max_requests_jitter: 0
  timeout: 30
  graceful_timeout: 30
  keepalive: 2
  limit_request_line: 4094
  limit_request_fields: 100
  limit_request_field_size: 8190
  reload: False
  reload_engine: auto
  reload_extra_files: []
  spew: False
  check_config: False
  preload_app: False
  sendfile: None
  reuse_port: False
  chdir: /home/ubuntu/workspace/spoti_env/spotifollow/spotifollow
  daemon: False
  raw_env: []
  pidfile: None
  worker_tmp_dir: None
  user: 998
  group: 998
  umask: 0
  initgroups: False
  tmp_upload_dir: None
  secure_scheme_headers: {'X-FORWARDED-PROTOCOL': 'ssl', 'X-FORWARDED-PROTO': 'https', 'X-FORWARDED-SSL': 'on'}
  forwarded_allow_ips: ['127.0.0.1']
  accesslog: None
  disable_redirect_access_to_syslog: False
  access_log_format: %(h)s %(l)s %(u)s %(t)s "%(r)s" %(s)s %(b)s "%(f)s" "%(a)s"
  errorlog: /home/ubuntu/workspace/spoti_env/spotifollow/spotifollow/spotifollow.log
  loglevel: debug
  capture_output: False
  logger_class: gunicorn.glogging.Logger
  logconfig: None
  logconfig_dict: {}
  syslog_addr: udp://localhost:514
  syslog: False
  syslog_prefix: None
  syslog_facility: user
  enable_stdio_inheritance: False
  statsd_host: None
  statsd_prefix: 
  proc_name: spotifollow_app
  default_proc_name: spotifollow.wsgi:application
  pythonpath: None
  paste: None
  on_starting: <function OnStarting.on_starting at 0x7f78cb59a950>
  on_reload: <function OnReload.on_reload at 0x7f78cb59aa60>
  when_ready: <function WhenReady.when_ready at 0x7f78cb59ab70>
  pre_fork: <function Prefork.pre_fork at 0x7f78cb59ac80>
  post_fork: <function Postfork.post_fork at 0x7f78cb59ad90>
  post_worker_init: <function PostWorkerInit.post_worker_init at 0x7f78cb59aea0>
  worker_int: <function WorkerInt.worker_int at 0x7f78cb0aa048>
  worker_abort: <function WorkerAbort.worker_abort at 0x7f78cb0aa158>
  pre_exec: <function PreExec.pre_exec at 0x7f78cb0aa268>
  pre_request: <function PreRequest.pre_request at 0x7f78cb0aa378>
  post_request: <function PostRequest.post_request at 0x7f78cb0aa400>
  child_exit: <function ChildExit.child_exit at 0x7f78cb0aa510>
  worker_exit: <function WorkerExit.worker_exit at 0x7f78cb0aa620>
  nworkers_changed: <function NumWorkersChanged.nworkers_changed at 0x7f78cb0aa730>
  on_exit: <function OnExit.on_exit at 0x7f78cb0aa840>
  proxy_protocol: False
  proxy_allow_ips: ['127.0.0.1']
  keyfile: None
  certfile: None
  ssl_version: 2
  cert_reqs: 0
  ca_certs: None
  suppress_ragged_eofs: True
  do_handshake_on_connect: False
  ciphers: TLSv1
  raw_paste_global_conf: []
[2019-07-01 16:39:13 +0000] [18502] [INFO] Starting gunicorn 19.9.0
[2019-07-01 16:39:13 +0000] [18502] [DEBUG] Arbiter booted
[2019-07-01 16:39:13 +0000] [18502] [INFO] Listening at: unix:/home/ubuntu/workspace/spoti_env/run/gunicorn.sock (18502)
[2019-07-01 16:39:13 +0000] [18502] [INFO] Using worker: sync
[2019-07-01 16:39:13 +0000] [18505] [INFO] Booting worker with pid: 18505
[2019-07-01 16:39:13 +0000] [18506] [INFO] Booting worker with pid: 18506
[2019-07-01 16:39:13 +0000] [18507] [INFO] Booting worker with pid: 18507
[2019-07-01 16:39:14 +0000] [18502] [DEBUG] 3 workers
[2019-07-01 16:39:14 +0000] [18505] [ERROR] Exception in worker process
Traceback (most recent call last):
  File "/home/ubuntu/workspace/spoti_env/lib/python3.6/site-packages/gunicorn/arbiter.py", line 583, in spawn_worker
    worker.init_process()
  File "/home/ubuntu/workspace/spoti_env/lib/python3.6/site-packages/gunicorn/workers/base.py", line 129, in init_process
    self.load_wsgi()
  File "/home/ubuntu/workspace/spoti_env/lib/python3.6/site-packages/gunicorn/workers/base.py", line 138, in load_wsgi
    self.wsgi = self.app.wsgi()
  File "/home/ubuntu/workspace/spoti_env/lib/python3.6/site-packages/gunicorn/app/base.py", line 67, in wsgi
    self.callable = self.load()
  File "/home/ubuntu/workspace/spoti_env/lib/python3.6/site-packages/gunicorn/app/wsgiapp.py", line 52, in load
    return self.load_wsgiapp()
  File "/home/ubuntu/workspace/spoti_env/lib/python3.6/site-packages/gunicorn/app/wsgiapp.py", line 41, in load_wsgiapp
    return util.import_app(self.app_uri)
  File "/home/ubuntu/workspace/spoti_env/lib/python3.6/site-packages/gunicorn/util.py", line 350, in import_app
    __import__(module)
  File "/home/ubuntu/workspace/spoti_env/spotifollow/spotifollow/spotifollow/wsgi.py", line 16, in <module>
    application = get_wsgi_application()
  File "/home/ubuntu/workspace/spoti_env/lib/python3.6/site-packages/django/core/wsgi.py", line 12, in get_wsgi_application
    django.setup(set_prefix=False)
  File "/home/ubuntu/workspace/spoti_env/lib/python3.6/site-packages/django/__init__.py", line 19, in setup
    configure_logging(settings.LOGGING_CONFIG, settings.LOGGING)
  File "/home/ubuntu/workspace/spoti_env/lib/python3.6/site-packages/django/conf/__init__.py", line 79, in __getattr__
    self._setup(name)
  File "/home/ubuntu/workspace/spoti_env/lib/python3.6/site-packages/django/conf/__init__.py", line 66, in _setup
    self._wrapped = Settings(settings_module)
  File "/home/ubuntu/workspace/spoti_env/lib/python3.6/site-packages/django/conf/__init__.py", line 176, in __init__
    raise ImproperlyConfigured("The SECRET_KEY setting must not be empty.")
django.core.exceptions.ImproperlyConfigured: The SECRET_KEY setting must not be empty.
[2019-07-01 16:39:14 +0000] [18505] [INFO] Worker exiting (pid: 18505)
[2019-07-01 16:39:14 +0000] [18506] [ERROR] Exception in worker process
Traceback (most recent call last):
  File "/home/ubuntu/workspace/spoti_env/lib/python3.6/site-packages/gunicorn/arbiter.py", line 583, in spawn_worker
    worker.init_process()
  File "/home/ubuntu/workspace/spoti_env/lib/python3.6/site-packages/gunicorn/workers/base.py", line 129, in init_process
    self.load_wsgi()
  File "/home/ubuntu/workspace/spoti_env/lib/python3.6/site-packages/gunicorn/workers/base.py", line 138, in load_wsgi
    self.wsgi = self.app.wsgi()
  File "/home/ubuntu/workspace/spoti_env/lib/python3.6/site-packages/gunicorn/app/base.py", line 67, in wsgi
    self.callable = self.load()
  File "/home/ubuntu/workspace/spoti_env/lib/python3.6/site-packages/gunicorn/app/wsgiapp.py", line 52, in load
    return self.load_wsgiapp()
  File "/home/ubuntu/workspace/spoti_env/lib/python3.6/site-packages/gunicorn/app/wsgiapp.py", line 41, in load_wsgiapp
    return util.import_app(self.app_uri)
  File "/home/ubuntu/workspace/spoti_env/lib/python3.6/site-packages/gunicorn/util.py", line 350, in import_app
    __import__(module)
  File "/home/ubuntu/workspace/spoti_env/spotifollow/spotifollow/spotifollow/wsgi.py", line 16, in <module>
    application = get_wsgi_application()
  File "/home/ubuntu/workspace/spoti_env/lib/python3.6/site-packages/django/core/wsgi.py", line 12, in get_wsgi_application
    django.setup(set_prefix=False)
  File "/home/ubuntu/workspace/spoti_env/lib/python3.6/site-packages/django/__init__.py", line 19, in setup
    configure_logging(settings.LOGGING_CONFIG, settings.LOGGING)
  File "/home/ubuntu/workspace/spoti_env/lib/python3.6/site-packages/django/conf/__init__.py", line 79, in __getattr__
    self._setup(name)
  File "/home/ubuntu/workspace/spoti_env/lib/python3.6/site-packages/django/conf/__init__.py", line 66, in _setup
    self._wrapped = Settings(settings_module)
  File "/home/ubuntu/workspace/spoti_env/lib/python3.6/site-packages/django/conf/__init__.py", line 176, in __init__
    raise ImproperlyConfigured("The SECRET_KEY setting must not be empty.")
django.core.exceptions.ImproperlyConfigured: The SECRET_KEY setting must not be empty.
[2019-07-01 16:39:14 +0000] [18506] [INFO] Worker exiting (pid: 18506)
[2019-07-01 16:39:14 +0000] [18507] [ERROR] Exception in worker process
Traceback (most recent call last):
  File "/home/ubuntu/workspace/spoti_env/lib/python3.6/site-packages/gunicorn/arbiter.py", line 583, in spawn_worker
    worker.init_process()
  File "/home/ubuntu/workspace/spoti_env/lib/python3.6/site-packages/gunicorn/workers/base.py", line 129, in init_process
    self.load_wsgi()
  File "/home/ubuntu/workspace/spoti_env/lib/python3.6/site-packages/gunicorn/workers/base.py", line 138, in load_wsgi
    self.wsgi = self.app.wsgi()
  File "/home/ubuntu/workspace/spoti_env/lib/python3.6/site-packages/gunicorn/app/base.py", line 67, in wsgi
    self.callable = self.load()
  File "/home/ubuntu/workspace/spoti_env/lib/python3.6/site-packages/gunicorn/app/wsgiapp.py", line 52, in load
    return self.load_wsgiapp()
  File "/home/ubuntu/workspace/spoti_env/lib/python3.6/site-packages/gunicorn/app/wsgiapp.py", line 41, in load_wsgiapp
    return util.import_app(self.app_uri)
  File "/home/ubuntu/workspace/spoti_env/lib/python3.6/site-packages/gunicorn/util.py", line 350, in import_app
    __import__(module)
  File "/home/ubuntu/workspace/spoti_env/spotifollow/spotifollow/spotifollow/wsgi.py", line 16, in <module>
    application = get_wsgi_application()
  File "/home/ubuntu/workspace/spoti_env/lib/python3.6/site-packages/django/core/wsgi.py", line 12, in get_wsgi_application
    django.setup(set_prefix=False)
  File "/home/ubuntu/workspace/spoti_env/lib/python3.6/site-packages/django/__init__.py", line 19, in setup
    configure_logging(settings.LOGGING_CONFIG, settings.LOGGING)
  File "/home/ubuntu/workspace/spoti_env/lib/python3.6/site-packages/django/conf/__init__.py", line 79, in __getattr__
    self._setup(name)
  File "/home/ubuntu/workspace/spoti_env/lib/python3.6/site-packages/django/conf/__init__.py", line 66, in _setup
    self._wrapped = Settings(settings_module)
  File "/home/ubuntu/workspace/spoti_env/lib/python3.6/site-packages/django/conf/__init__.py", line 176, in __init__
    raise ImproperlyConfigured("The SECRET_KEY setting must not be empty.")
django.core.exceptions.ImproperlyConfigured: The SECRET_KEY setting must not be empty.
[2019-07-01 16:39:14 +0000] [18507] [INFO] Worker exiting (pid: 18507)
[2019-07-01 16:39:14 +0000] [18502] [INFO] Shutting down: Master
[2019-07-01 16:39:14 +0000] [18502] [INFO] Reason: Worker failed to boot.
[2019-07-01 16:46:40 +0000] [18565] [DEBUG] Current configuration:
  config: None
  bind: ['unix:/home/ubuntu/workspace/spoti_env/run/gunicorn.sock']
  backlog: 2048
  workers: 3
  worker_class: sync
  threads: 1
  worker_connections: 1000
  max_requests: 0
  max_requests_jitter: 0
  timeout: 30
  graceful_timeout: 30
  keepalive: 2
  limit_request_line: 4094
  limit_request_fields: 100
  limit_request_field_size: 8190
  reload: False
  reload_engine: auto
  reload_extra_files: []
  spew: False
  check_config: False
  preload_app: False
  sendfile: None
  reuse_port: False
  chdir: /home/ubuntu/workspace/spoti_env/spotifollow/spotifollow
  daemon: False
  raw_env: []
  pidfile: None
  worker_tmp_dir: None
  user: 998
  group: 998
  umask: 0
  initgroups: False
  tmp_upload_dir: None
  secure_scheme_headers: {'X-FORWARDED-PROTOCOL': 'ssl', 'X-FORWARDED-PROTO': 'https', 'X-FORWARDED-SSL': 'on'}
  forwarded_allow_ips: ['127.0.0.1']
  accesslog: None
  disable_redirect_access_to_syslog: False
  access_log_format: %(h)s %(l)s %(u)s %(t)s "%(r)s" %(s)s %(b)s "%(f)s" "%(a)s"
  errorlog: /home/ubuntu/workspace/spoti_env/spotifollow/spotifollow/spotifollow.log
  loglevel: debug
  capture_output: False
  logger_class: gunicorn.glogging.Logger
  logconfig: None
  logconfig_dict: {}
  syslog_addr: udp://localhost:514
  syslog: False
  syslog_prefix: None
  syslog_facility: user
  enable_stdio_inheritance: False
  statsd_host: None
  statsd_prefix: 
  proc_name: spotifollow_app
  default_proc_name: spotifollow.wsgi:application
  pythonpath: None
  paste: None
  on_starting: <function OnStarting.on_starting at 0x7fd4d0927950>
  on_reload: <function OnReload.on_reload at 0x7fd4d0927a60>
  when_ready: <function WhenReady.when_ready at 0x7fd4d0927b70>
  pre_fork: <function Prefork.pre_fork at 0x7fd4d0927c80>
  post_fork: <function Postfork.post_fork at 0x7fd4d0927d90>
  post_worker_init: <function PostWorkerInit.post_worker_init at 0x7fd4d0927ea0>
  worker_int: <function WorkerInt.worker_int at 0x7fd4d0437048>
  worker_abort: <function WorkerAbort.worker_abort at 0x7fd4d0437158>
  pre_exec: <function PreExec.pre_exec at 0x7fd4d0437268>
  pre_request: <function PreRequest.pre_request at 0x7fd4d0437378>
  post_request: <function PostRequest.post_request at 0x7fd4d0437400>
  child_exit: <function ChildExit.child_exit at 0x7fd4d0437510>
  worker_exit: <function WorkerExit.worker_exit at 0x7fd4d0437620>
  nworkers_changed: <function NumWorkersChanged.nworkers_changed at 0x7fd4d0437730>
  on_exit: <function OnExit.on_exit at 0x7fd4d0437840>
  proxy_protocol: False
  proxy_allow_ips: ['127.0.0.1']
  keyfile: None
  certfile: None
  ssl_version: 2
  cert_reqs: 0
  ca_certs: None
  suppress_ragged_eofs: True
  do_handshake_on_connect: False
  ciphers: TLSv1
  raw_paste_global_conf: []
[2019-07-01 16:46:40 +0000] [18565] [INFO] Starting gunicorn 19.9.0
[2019-07-01 16:46:40 +0000] [18565] [DEBUG] Arbiter booted
[2019-07-01 16:46:40 +0000] [18565] [INFO] Listening at: unix:/home/ubuntu/workspace/spoti_env/run/gunicorn.sock (18565)
[2019-07-01 16:46:40 +0000] [18565] [INFO] Using worker: sync
[2019-07-01 16:46:40 +0000] [18568] [INFO] Booting worker with pid: 18568
[2019-07-01 16:46:40 +0000] [18569] [INFO] Booting worker with pid: 18569
[2019-07-01 16:46:40 +0000] [18571] [INFO] Booting worker with pid: 18571
[2019-07-01 16:46:40 +0000] [18565] [DEBUG] 3 workers
[2019-07-01 16:47:16 +0000] [18595] [DEBUG] Current configuration:
  config: None
  bind: ['unix:/home/ubuntu/workspace/spoti_env/run/gunicorn.sock']
  backlog: 2048
  workers: 3
  worker_class: sync
  threads: 1
  worker_connections: 1000
  max_requests: 0
  max_requests_jitter: 0
  timeout: 30
  graceful_timeout: 30
  keepalive: 2
  limit_request_line: 4094
  limit_request_fields: 100
  limit_request_field_size: 8190
  reload: False
  reload_engine: auto
  reload_extra_files: []
  spew: False
  check_config: False
  preload_app: False
  sendfile: None
  reuse_port: False
  chdir: /home/ubuntu/workspace/spoti_env/spotifollow/spotifollow
  daemon: False
  raw_env: []
  pidfile: None
  worker_tmp_dir: None
  user: 998
  group: 998
  umask: 0
  initgroups: False
  tmp_upload_dir: None
  secure_scheme_headers: {'X-FORWARDED-PROTOCOL': 'ssl', 'X-FORWARDED-PROTO': 'https', 'X-FORWARDED-SSL': 'on'}
  forwarded_allow_ips: ['127.0.0.1']
  accesslog: None
  disable_redirect_access_to_syslog: False
  access_log_format: %(h)s %(l)s %(u)s %(t)s "%(r)s" %(s)s %(b)s "%(f)s" "%(a)s"
  errorlog: /home/ubuntu/workspace/spoti_env/spotifollow/spotifollow/spotifollow.log
  loglevel: debug
  capture_output: False
  logger_class: gunicorn.glogging.Logger
  logconfig: None
  logconfig_dict: {}
  syslog_addr: udp://localhost:514
  syslog: False
  syslog_prefix: None
  syslog_facility: user
  enable_stdio_inheritance: False
  statsd_host: None
  statsd_prefix: 
  proc_name: spotifollow_app
  default_proc_name: spotifollow.wsgi:application
  pythonpath: None
  paste: None
  on_starting: <function OnStarting.on_starting at 0x7f413843b950>
  on_reload: <function OnReload.on_reload at 0x7f413843ba60>
  when_ready: <function WhenReady.when_ready at 0x7f413843bb70>
  pre_fork: <function Prefork.pre_fork at 0x7f413843bc80>
  post_fork: <function Postfork.post_fork at 0x7f413843bd90>
  post_worker_init: <function PostWorkerInit.post_worker_init at 0x7f413843bea0>
  worker_int: <function WorkerInt.worker_int at 0x7f4137f4b048>
  worker_abort: <function WorkerAbort.worker_abort at 0x7f4137f4b158>
  pre_exec: <function PreExec.pre_exec at 0x7f4137f4b268>
  pre_request: <function PreRequest.pre_request at 0x7f4137f4b378>
  post_request: <function PostRequest.post_request at 0x7f4137f4b400>
  child_exit: <function ChildExit.child_exit at 0x7f4137f4b510>
  worker_exit: <function WorkerExit.worker_exit at 0x7f4137f4b620>
  nworkers_changed: <function NumWorkersChanged.nworkers_changed at 0x7f4137f4b730>
  on_exit: <function OnExit.on_exit at 0x7f4137f4b840>
  proxy_protocol: False
  proxy_allow_ips: ['127.0.0.1']
  keyfile: None
  certfile: None
  ssl_version: 2
  cert_reqs: 0
  ca_certs: None
  suppress_ragged_eofs: True
  do_handshake_on_connect: False
  ciphers: TLSv1
  raw_paste_global_conf: []
[2019-07-01 16:47:16 +0000] [18595] [INFO] Starting gunicorn 19.9.0
[2019-07-01 16:47:16 +0000] [18595] [DEBUG] Arbiter booted
[2019-07-01 16:47:16 +0000] [18595] [INFO] Listening at: unix:/home/ubuntu/workspace/spoti_env/run/gunicorn.sock (18595)
[2019-07-01 16:47:16 +0000] [18595] [INFO] Using worker: sync
[2019-07-01 16:47:16 +0000] [18598] [INFO] Booting worker with pid: 18598
[2019-07-01 16:47:16 +0000] [18599] [INFO] Booting worker with pid: 18599
[2019-07-01 16:47:16 +0000] [18600] [INFO] Booting worker with pid: 18600
[2019-07-01 16:47:16 +0000] [18595] [DEBUG] 3 workers
[2019-07-01 16:54:21 +0000] [18565] [INFO] Handling signal: term
Traceback (most recent call last):
  File "/home/ubuntu/workspace/spoti_env/lib/python3.6/site-packages/gunicorn/arbiter.py", line 225, in run
    handler()
  File "/home/ubuntu/workspace/spoti_env/lib/python3.6/site-packages/gunicorn/arbiter.py", line 260, in handle_term
    raise StopIteration
StopIteration

During handling of the above exception, another exception occurred:

Traceback (most recent call last):
  File "/home/ubuntu/workspace/spoti_env/spotifollow/spotifollow/../../bin/gunicorn", line 10, in <module>
    sys.exit(run())
  File "/home/ubuntu/workspace/spoti_env/lib/python3.6/site-packages/gunicorn/app/wsgiapp.py", line 61, in run
    WSGIApplication("%(prog)s [OPTIONS] [APP_MODULE]").run()
  File "/home/ubuntu/workspace/spoti_env/lib/python3.6/site-packages/gunicorn/app/base.py", line 223, in run
    super(Application, self).run()
  File "/home/ubuntu/workspace/spoti_env/lib/python3.6/site-packages/gunicorn/app/base.py", line 72, in run
    Arbiter(self).run()
  File "/home/ubuntu/workspace/spoti_env/lib/python3.6/site-packages/gunicorn/arbiter.py", line 228, in run
    self.halt()
  File "/home/ubuntu/workspace/spoti_env/lib/python3.6/site-packages/gunicorn/arbiter.py", line 345, in halt
    self.stop()
  File "/home/ubuntu/workspace/spoti_env/lib/python3.6/site-packages/gunicorn/arbiter.py", line 382, in stop
    sock.close_sockets(self.LISTENERS, unlink)
  File "/home/ubuntu/workspace/spoti_env/lib/python3.6/site-packages/gunicorn/sock.py", line 209, in close_sockets
    os.unlink(sock_name)
FileNotFoundError: [Errno 2] No such file or directory: '/home/ubuntu/workspace/spoti_env/run/gunicorn.sock'
[2019-07-01 16:54:21 +0000] [18568] [INFO] Worker exiting (pid: 18568)
[2019-07-01 16:54:21 +0000] [18569] [INFO] Worker exiting (pid: 18569)
[2019-07-01 16:54:21 +0000] [18571] [INFO] Worker exiting (pid: 18571)
[2019-07-01 16:54:21 +0000] [18595] [INFO] Handling signal: term
Traceback (most recent call last):
  File "/home/ubuntu/workspace/spoti_env/lib/python3.6/site-packages/gunicorn/arbiter.py", line 225, in run
    handler()
  File "/home/ubuntu/workspace/spoti_env/lib/python3.6/site-packages/gunicorn/arbiter.py", line 260, in handle_term
    raise StopIteration
StopIteration

During handling of the above exception, another exception occurred:

Traceback (most recent call last):
  File "/home/ubuntu/workspace/spoti_env/spotifollow/spotifollow/../../bin/gunicorn", line 10, in <module>
    sys.exit(run())
  File "/home/ubuntu/workspace/spoti_env/lib/python3.6/site-packages/gunicorn/app/wsgiapp.py", line 61, in run
    WSGIApplication("%(prog)s [OPTIONS] [APP_MODULE]").run()
  File "/home/ubuntu/workspace/spoti_env/lib/python3.6/site-packages/gunicorn/app/base.py", line 223, in run
    super(Application, self).run()
  File "/home/ubuntu/workspace/spoti_env/lib/python3.6/site-packages/gunicorn/app/base.py", line 72, in run
    Arbiter(self).run()
  File "/home/ubuntu/workspace/spoti_env/lib/python3.6/site-packages/gunicorn/arbiter.py", line 228, in run
    self.halt()
  File "/home/ubuntu/workspace/spoti_env/lib/python3.6/site-packages/gunicorn/arbiter.py", line 345, in halt
    self.stop()
  File "/home/ubuntu/workspace/spoti_env/lib/python3.6/site-packages/gunicorn/arbiter.py", line 382, in stop
    sock.close_sockets(self.LISTENERS, unlink)
  File "/home/ubuntu/workspace/spoti_env/lib/python3.6/site-packages/gunicorn/sock.py", line 209, in close_sockets
    os.unlink(sock_name)
FileNotFoundError: [Errno 2] No such file or directory: '/home/ubuntu/workspace/spoti_env/run/gunicorn.sock'
[2019-07-01 16:54:21 +0000] [18598] [INFO] Worker exiting (pid: 18598)
[2019-07-01 16:54:21 +0000] [18599] [INFO] Worker exiting (pid: 18599)
[2019-07-01 16:54:21 +0000] [18600] [INFO] Worker exiting (pid: 18600)
